Workbook

Sheet Calculo
A1: Ejecución del presupuesto y del tiempo · cierre del proyecto (Sprint 10)
A3: Línea base (SCRUM-11, SCRUM-24, SCRUM-36, SCRUM-57, SCRUM-72)
A4: Esfuerzo total estimado (H/H) | B4: 7613.67 | C4: SCRUM-11, Puntos de Casos de Uso
A5: Costo total estimado, K = 1.5 | B5: 511638.46 | C5: SCRUM-11
A6: Costo total estimado, K = 2 | B6: 682184.62 | C6: SCRUM-11
A7: Factor K bajo | B7: 1.5 | C7: Multiplica la tarifa horaria
A8: Factor K alto | B8: 2 | C8: Multiplica la tarifa horaria
A9: Peso de la actividad de implementación | B9: 0.4 | C9: Métrica dual, SCRUM-24 y SCRUM-36
A10: Horas acumuladas al cierre del Sprint 7 (H/H) | B10: 721 | C10: SCRUM-36
A11: Monto ejecutado al cierre del Sprint 7, K = 1.5 | B11: 48701.7 | C11: SCRUM-36
A12: Horas acumuladas al cierre del Sprint 9 (H/H) | B12: 899 | C12: SCRUM-72, ejecucion-presupuesto-sprint9.xlsx
A13: Monto ejecutado al cierre del Sprint 9, K = 1.5 | B13: 60841.2 | C13: SCRUM-72, ejecucion-presupuesto-sprint9.xlsx
A15: Horas y monto del Sprint 10 por integrante
A16: Integrante | B16: Tarifa (Q/h) | C16: Horas del S10 (H/H) | D16: % de las horas del S10 | E16: Monto base (Q) | F16: Monto K = 1.5 (Q) | G16: Monto K = 2 (Q) | H16: Fuente
A17: Pablo Vásquez | B17: 57 | C17: =SUMIF('Tareas S10'!$C$4:$C$34,A17,'Tareas S10'!$F$4:$F$34) | D17: =IF($C$22=0,0,C17/$C$22) | E17: =C17*B17 | F17: =E17*$B$7 | G17: =E17*$B$8 | H17: LOGT Vásquez (Jira SCRUM Sprint 5)
A18: Jonathan Tubac | B18: 51 | C18: =SUMIF('Tareas S10'!$C$4:$C$34,A18,'Tareas S10'!$F$4:$F$34) | D18: =IF($C$22=0,0,C18/$C$22) | E18: =C18*B18 | F18: =E18*$B$7 | G18: =E18*$B$8 | H18: LOGT Tubac (Jira SCRUM Sprint 5)
A19: Juan Francisco Montenegro Aguirre | B19: 46 | C19: =SUMIF('Tareas S10'!$C$4:$C$34,A19,'Tareas S10'!$F$4:$F$34) | D19: =IF($C$22=0,0,C19/$C$22) | E19: =C19*B19 | F19: =E19*$B$7 | G19: =E19*$B$8 | H19: LOGT Montenegro (Jira SCRUM Sprint 5)
A20: Alejandra Sarai Avilés González | B20: 36 | C20: =SUMIF('Tareas S10'!$C$4:$C$34,A20,'Tareas S10'!$F$4:$F$34) | D20: =IF($C$22=0,0,C20/$C$22) | E20: =C20*B20 | F20: =E20*$B$7 | G20: =E20*$B$8 | H20: LOGT Avilés (Jira SCRUM Sprint 5)
A21: Ivana Cristina Figueroa Diemek | B21: 34 | C21: =SUMIF('Tareas S10'!$C$4:$C$34,A21,'Tareas S10'!$F$4:$F$34) | D21: =IF($C$22=0,0,C21/$C$22) | E21: =C21*B21 | F21: =E21*$B$7 | G21: =E21*$B$8 | H21: LOGT Figueroa (Jira SCRUM Sprint 5)
A22: Total | B22: =IF(C22=0,0,E22/C22) | C22: =SUM(C17:C21) | D22: =SUM(D17:D21) | E22: =SUM(E17:E21) | F22: =SUM(F17:F21) | G22: =SUM(G17:G21)
A25: Horas acumuladas por integrante al cierre del proyecto (Sprints 8 a 10)
A26: Integrante | B26: Horas S8 (H/H) | C26: Horas S9 (H/H) | D26: Horas S10 (H/H) | E26: Total S8–S10 (H/H) | F26: Monto S8–S10, K = 1.5 | G26: Monto S8–S10, K = 2 | H26: Fuente
A27: Pablo Vásquez | B27: 16 | C27: 19 | D27: =C17 | E27: =SUM(B27:D27) | F27: =E27*B17*$B$7 | G27: =E27*B17*$B$8 | H27: LOGT S8 y S9 (libros anteriores) y LOGT S10
A28: Jonathan Tubac | B28: 22 | C28: 18 | D28: =C18 | E28: =SUM(B28:D28) | F28: =E28*B18*$B$7 | G28: =E28*B18*$B$8 | H28: LOGT S8 y S9 (libros anteriores) y LOGT S10
A29: Juan Francisco Montenegro Aguirre | B29: 18 | C29: 23 | D29: =C19 | E29: =SUM(B29:D29) | F29: =E29*B19*$B$7 | G29: =E29*B19*$B$8 | H29: LOGT S8 y S9 (libros anteriores) y LOGT S10
A30: Alejandra Sarai Avilés González | B30: 19 | C30: 13 | D30: =C20 | E30: =SUM(B30:D30) | F30: =E30*B20*$B$7 | G30: =E30*B20*$B$8 | H30: LOGT S8 y S9 (libros anteriores) y LOGT S10
A31: Ivana Cristina Figueroa Diemek | B31: 15 | C31: 15 | D31: =C21 | E31: =SUM(B31:D31) | F31: =E31*B21*$B$7 | G31: =E31*B21*$B$8 | H31: LOGT S8 y S9 (libros anteriores) y LOGT S10
A32: Total | B32: =SUM(B27:B31) | C32: =SUM(C27:C31) | D32: =SUM(D27:D31) | E32: =SUM(E27:E31) | F32: =SUM(F27:F31) | G32: =SUM(G27:G31)
A33: Los Sprints 1 a 7 (721.00 H/H) se reportaron consolidados en SCRUM-24 y SCRUM-36 y no se desglosan aquí por integrante.
A35: Resultados y variación respecto de los cortes anteriores
A36: Indicador | B36: Corte Sprint 7 | C36: Corte Sprint 9 | D36: Cierre Sprint 10 | E36: Variación vs S9 | F36: Variación vs S7
A37: Horas acumuladas (H/H) | B37: =B10 | C37: =B12 | D37: =B12+C22 | E37: =D37-C37 | F37: =D37-B37
A38: % del esfuerzo total (ciclo completo) | B38: =B37/$B$4 | C38: =C37/$B$4 | D38: =D37/$B$4 | E38: =(D38-C38)*100 | F38: =(D38-B38)*100
A39: % de la actividad de implementación (40 %) | B39: =B37/($B$4*$B$9) | C39: =C37/($B$4*$B$9) | D39: =D37/($B$4*$B$9) | E39: =(D39-C39)*100 | F39: =(D39-B39)*100
A40: Monto ejecutado, K = 1.5 | B40: =B11 | C40: =B13 | D40: =B13+F22 | E40: =D40-C40 | F40: =D40-B40
A41: % del costo total, K = 1.5 | B41: =B40/$B$5 | C41: =C40/$B$5 | D41: =D40/$B$5 | E41: =(D41-C41)*100 | F41: =(D41-B41)*100
A42: Monto ejecutado, K = 2 | B42: =B11/$B$7*$B$8 | C42: =B13/$B$7*$B$8 | D42: =C42+G22 | E42: =D42-C42 | F42: =D42-B42
A43: % del costo total, K = 2 | B43: =B42/$B$6 | C43: =C42/$B$6 | D43: =D42/$B$6 | E43: =(D43-C43)*100 | F43: =(D43-B43)*100
A44: % del costo de implementación, K = 1.5 | B44: =B40/($B$5*$B$9) | C44: =C40/($B$5*$B$9) | D44: =D40/($B$5*$B$9) | E44: =(D44-C44)*100 | F44: =(D44-B44)*100
A45: % del costo de implementación, K = 2 | B45: =B42/($B$6*$B$9) | C45: =C42/($B$6*$B$9) | D45: =D42/($B$6*$B$9) | E45: =(D45-C45)*100 | F45: =(D45-B45)*100
...

Sheet Tareas S10
A1: Tareas del Sprint 10 en Jira (SCRUM Sprint 5) y horas registradas
A3: Clave | B3: Tarea | C3: Responsable | D3: SP | E3: Horas estimadas en Jira | F3: Horas en LOGT | G3: Diferencia | H3: Estado en Jira | I3: Origen de las horas
A4: SCRUM-106 | B4: UI-2 · Consistencia de superficies, correcciones de layout y página 404 | C4: Pablo Vásquez | D4: 5 | F4: =SUMIF('LOGT Vásquez'!$G:$G,A4,'LOGT Vásquez'!$E:$E)/60 | G4: =IF(E4="","",F4-E4) | H4: Finalizado | I4: Derivada de SP (2.57 h/SP)
A5: SCRUM-69 | B5: DT-08 · Actualizar dependencias vulnerables y auditar en CI | C5: Pablo Vásquez | D5: 3 | E5: 5 | F5: =SUMIF('LOGT Vásquez'!$G:$G,A5,'LOGT Vásquez'!$E:$E)/60 | G5: =IF(E5="","",F5-E5) | H5: Finalizado | I5: Estimación de Jira
A6: SCRUM-77 | B6: DT-11 · ESLint, Prettier y paso de lint en el pipeline | C6: Pablo Vásquez | D6: 3 | E6: 8 | F6: =SUMIF('LOGT Vásquez'!$G:$G,A6,'LOGT Vásquez'!$E:$E)/60 | G6: =IF(E6="","",F6-E6) | H6: Finalizado | I6: Estimación de Jira
A7: SCRUM-82 | B7: PAY-1 · Módulo de suscripciones con pasarela de pago en modo de prueba | C7: Pablo Vásquez | D7: 8 | E7: 21 | F7: =SUMIF('LOGT Vásquez'!$G:$G,A7,'LOGT Vásquez'!$E:$E)/60 | G7: =IF(E7="","",F7-E7) | H7: Finalizado | I7: Estimación de Jira
A8: SCRUM-86 | B8: L-5 · Aviso de uso del asistente de IA | C8: Pablo Vásquez | D8: 2 | E8: 5 | F8: =SUMIF('LOGT Vásquez'!$G:$G,A8,'LOGT Vásquez'!$E:$E)/60 | G8: =IF(E8="","",F8-E8) | H8: Finalizado | I8: Estimación de Jira
A9: SCRUM-94 | B9: PROD-1 · Servidor de producción con URL pública verificable | C9: Pablo Vásquez | D9: 5 | E9: 13 | F9: =SUMIF('LOGT Vásquez'!$G:$G,A9,'LOGT Vásquez'!$E:$E)/60 | G9: =IF(E9="","",F9-E9) | H9: Finalizado | I9: Estimación de Jira
A10: SCRUM-99 | B10: CI-1 · Evidencia de integración continua y comparación de rendimiento | C10: Pablo Vásquez | D10: 3 | E10: 8 | F10: =SUMIF('LOGT Vásquez'!$G:$G,A10,'LOGT Vásquez'!$E:$E)/60 | G10: =IF(E10="","",F10-E10) | H10: En curso | I10: Estimación de Jira
A11: SCRUM-102 | B11: BUD-1 · Presupuesto y tiempo ejecutado al cierre del proyecto | C11: Jonathan Tubac | D11: 3 | E11: 8 | F11: =SUMIF('LOGT Tubac'!$G:$G,A11,'LOGT Tubac'!$E:$E)/60 | G11: =IF(E11="","",F11-E11) | H11: En curso | I11: Estimación de Jira
A12: SCRUM-78 | B12: L-7 · Análisis de brecha fiscal del POS frente al régimen FEL de la SAT | C12: Jonathan Tubac | D12: 3 | E12: 8 | F12: =SUMIF('LOGT Tubac'!$G:$G,A12,'LOGT Tubac'!$E:$E)/60 | G12: =IF(E12="","",F12-E12) | H12: Finalizado | I12: Estimación de Jira
A13: SCRUM-87 | B13: L-3 · Política de cookies y almacenamiento local, con banner de consentimiento | C13: Jonathan Tubac | D13: 3 | E13: 8 | F13: =SUMIF('LOGT Tubac'!$G:$G,A13,'LOGT Tubac'!$E:$E)/60 | G13: =IF(E13="","",F13-E13) | H13: Finalizado | I13: Estimación de Jira
A14: SCRUM-88 | B14: L-6 · Implementación de los documentos legales en la aplicación | C14: Jonathan Tubac | D14: 5 | E14: 13 | F14: =SUMIF('LOGT Tubac'!$G:$G,A14,'LOGT Tubac'!$E:$E)/60 | G14: =IF(E14="","",F14-E14) | H14: Finalizado | I14: Estimación de Jira
A15: SCRUM-95 | B15: TEST-1 · Suite de pruebas de integración en el pipeline de CI | C15: Jonathan Tubac | D15: 5 | E15: 13 | F15: =SUMIF('LOGT Tubac'!$G:$G,A15,'LOGT Tubac'!$E:$E)/60 | G15: =IF(E15="","",F15-E15) | H15: Finalizado | I15: Estimación de Jira
A16: SCRUM-97 | B16: TEST-2 · Medición y reporte de la evidencia de prueba del 80 % del sistema | C16: Jonathan Tubac | D16: 3 | E16: 8 | F16: =SUMIF('LOGT Tubac'!$G:$G,A16,'LOGT Tubac'!$E:$E)/60 | G16: =IF(E16="","",F16-E16) | H16: Finalizado | I16: Estimación de Jira
A17: SCRUM-103 | B17: UI-1 · Correcciones de interfaz: responsive del fondo, escala tipográfica y tamaño de fuente configurable | C17: Juan Francisco Montenegro Aguirre | D17: 5 | E17: 13 | F17: =SUMIF('LOGT Montenegro'!$G:$G,A17,'LOGT Montenegro'!$E:$E)/60 | G17: =IF(E17="","",F17-E17) | H17: En revisión | I17: Estimación de Jira
A18: SCRUM-76 | B18: L-0 · Investigación del marco legal aplicable y estándar de cumplimiento adoptado | C18: Juan Francisco Montenegro Aguirre | D18: 3 | E18: 8 | F18: =SUMIF('LOGT Montenegro'!$G:$G,A18,'LOGT Montenegro'!$E:$E)/60 | G18: =IF(E18="","",F18-E18) | H18: Finalizado | I18: Estimación de Jira
A19: SCRUM-80 | B19: L-8 · Licencia del repositorio y auditoría de licencias de terceros | C19: Juan Francisco Montenegro Aguirre | D19: 3 | E19: 8 | F19: =SUMIF('LOGT Montenegro'!$G:$G,A19,'LOGT Montenegro'!$E:$E)/60 | G19: =IF(E19="","",F19-E19) | H19: Finalizado | I19: Estimación de Jira
A20: SCRUM-83 | B20: L-1 · Términos y Condiciones de Uso | C20: Juan Francisco Montenegro Aguirre | D20: 6 | E20: 16 | F20: =SUMIF('LOGT Montenegro'!$G:$G,A20,'LOGT Montenegro'!$E:$E)/60 | G20: =IF(E20="","",F20-E20) | H20: Finalizado | I20: Estimación de Jira
A21: SCRUM-84 | B21: L-2 · Política de Privacidad e inventario de datos personales del sistema | C21: Juan Francisco Montenegro Aguirre | D21: 5 | E21: 13 | F21: =SUMIF('LOGT Montenegro'!$G:$G,A21,'LOGT Montenegro'!$E:$E)/60 | G21: =IF(E21="","",F21-E21) | H21: Finalizado | I21: Estimación de Jira
A22: SCRUM-85 | B22: L-4 · Adenda de tratamiento de datos para los clientes de Kontrol | C22: Juan Francisco Montenegro Aguirre | D22: 3 | E22: 8 | F22: =SUMIF('LOGT Montenegro'!$G:$G,A22,'LOGT Montenegro'!$E:$E)/60 | G22: =IF(E22="","",F22-E22) | H22: En revisión | I22: Estimación de Jira
A23: SCRUM-96 | B23: RTF-1 · Revisión Técnica Formal 2: hallazgos y plan de resolución | C23: Juan Francisco Montenegro Aguirre | D23: 3 | E23: 8 | F23: =SUMIF('LOGT Montenegro'!$G:$G,A23,'LOGT Montenegro'!$E:$E)/60 | G23: =IF(E23="","",F23-E23) | H23: En revisión | I23: Estimación de Jira
A24: SCRUM-101 | B24: DEMO-1 · Muestra del incremento a usuarios finales | C24: Alejandra Sarai Avilés González | D24: 2 | E24: 5 | F24: =SUMIF('LOGT Avilés'!$G:$G,A24,'LOGT Avilés'!$E:$E)/60 | G24: =IF(E24="","",F24-E24) | H24: Por hacer | I24: Sin trabajo registrado al corte
A25: SCRUM-66 | B25: DT-16 · Aislar las vistas temporales del agente dentro de la transacción | C25: Alejandra Sarai Avilés González | D25: 3 | E25: 5 | F25: =SUMIF('LOGT Avilés'!$G:$G,A25,'LOGT Avilés'!$E:$E)/60 | G25: =IF(E25="","",F25-E25) | H25: Finalizado | I25: Estimación de Jira
A26: SCRUM-75 | B26: DT-07 · Capa de acceso a API unificada en el frontend | C26: Alejandra Sarai Avilés González | D26: 5 | E26: 13 | F26: =SUMIF('LOGT Avilés'!$G:$G,A26,'LOGT Avilés'!$E:$E)/60 | G26: =IF(E26="","",F26-E26) | H26: Finalizado | I26: Estimación de Jira
A27: SCRUM-89 | B27: P-1 · Exportación de datos y borrado de cuenta | C27: Alejandra Sarai Avilés González | D27: 5 | E27: 13 | F27: =SUMIF('LOGT Avilés'!$G:$G,A27,'LOGT Avilés'!$E:$E)/60 | G27: =IF(E27="","",F27-E27) | H27: Finalizado | I27: Estimación de Jira
A28: SCRUM-90 | B28: P-2 · Política de respaldos con restauración probada | C28: Alejandra Sarai Avilés González | D28: 3 | E28: 8 | F28: =SUMIF('LOGT Avilés'!$G:$G,A28,'LOGT Avilés'!$E:$E)/60 | G28: =IF(E28="","",F28-E28) | H28: En revisión | I28: Estimación de Jira
A29: SCRUM-98 | B29: UX-N · Resultados de las pruebas de UX y reflexión sobre el uso del neurolab | C29: Alejandra Sarai Avilés González | D29: 3 | E29: 8 | F29: =SUMIF('LOGT Avilés'!$G:$G,A29,'LOGT Avilés'!$E:$E)/60 | G29: =IF(E29="","",F29-E29) | H29: Finalizado | I29: Estimación de Jira
A30: SCRUM-100 | B30: TEST-3 · Reporte consolidado de pruebas de regresión de la refactorización | C30: Ivana Cristina Figueroa Diemek | D30: 2 | E30: 5 | F30: =SUMIF('LOGT Figueroa'!$G:$G,A30,'LOGT Figueroa'!$E:$E)/60 | G30: =IF(E30="","",F30-E30) | H30: En revisión | I30: Estimación de Jira
A31: SCRUM-79 | B31: HU-32b · Cierre de la Fase 2 de la identidad visual v2 | C31: Ivana Cristina Figueroa Diemek | D31: 5 | E31: 13 | F31: =SUMIF('LOGT Figueroa'!$G:$G,A31,'LOGT Figueroa'!$E:$E)/60 | G31: =IF(E31="","",F31-E31) | H31: Finalizado | I31: Estimación de Jira
A32: SCRUM-91 | B32: P-3 · Procedimiento de respuesta a incidentes y notificación de brechas | C32: Ivana Cristina Figueroa Diemek | D32: 2 | E32: 5 | F32: =SUMIF('LOGT Figueroa'!$G:$G,A32,'LOGT Figueroa'!$E:$E)/60 | G32: =IF(E32="","",F32-E32) | H32: En curso | I32: Estimación de Jira
A33: SCRUM-92 | B33: DT-17 · Carga diferida del logo 3D y los fondos animados, y separación de chunks | C33: Ivana Cristina Figueroa Diemek | D33: 5 | E33: 13 | F33: =SUMIF('LOGT Figueroa'!$G:$G,A33,'LOGT Figueroa'!$E:$E)/60 | G33: =IF(E33="","",F33-E33) | H33: Finalizado | I33: Estimación de Jira
A34: SCRUM-93 | B34: DT-09 · Tema claro, escala de z-index y retiro de alias legacy | C34: Ivana Cristina Figueroa Diemek | D34: 4 | E34: 10 | F34: =SUMIF('LOGT Figueroa'!$G:$G,A34,'LOGT Figueroa'!$E:$E)/60 | G34: =IF(E34="","",F34-E34) | H34: Finalizado | I34: Estimación de Jira
A35: Total | D35: =SUM(D4:D34) | E35: =SUM(E4:E34) | F35: =SUM(F4:F34)
A37: Las horas en LOGT salen de la estimación original de cada tarea en Jira, igual que en los cortes de los Sprints 8 y 9. UI-2 no tiene estimación: se deriva de sus SP con la razón del sprint (2.57 h/SP). DEMO-1 sigue «Por hacer» al corte y no suma horas. Estados de Jira consultados el 27/10/2026.

Sheet Serie
A1: Serie de cortes: horas y monto acumulados
A2: Corte | B2: Horas del periodo (H/H) | C2: Horas acumuladas (H/H) | D2: % del esfuerzo total | E2: Monto acumulado K = 1.5 | F2: % del costo K = 1.5 | G2: Fuente
A3: Sprints 1 a 4 | B3: 514.5 | C3: 514.5 | D3: =C3/Calculo!$B$4 | E3: No reportado por separado | G3: LOGT, reportado en SCRUM-24
A4: Sprints 5 a 7 | B4: 206.5 | C4: 721 | D4: =C4/Calculo!$B$4 | E4: 48701.7 | F4: =E4/Calculo!$B$5 | G4: SCRUM-36
A5: Sprint 8 | B5: 90 | C5: 811 | D5: =C5/Calculo!$B$4 | E5: 54785.7 | F5: =E5/Calculo!$B$5 | G5: SCRUM-57, ejecucion-presupuesto-sprint8.xlsx
A6: Sprint 9 | B6: 88 | C6: 899 | D6: =C6/Calculo!$B$4 | E6: 60841.2 | F6: =E6/Calculo!$B$5 | G6: SCRUM-72, ejecucion-presupuesto-sprint9.xlsx
A7: Sprint 10 (cierre) | B7: =Calculo!C22 | C7: =Calculo!D37 | D7: =C7/Calculo!$B$4 | E7: =Calculo!D40 | F7: =E7/Calculo!$B$5 | G7: SCRUM-102, este libro
A9: El corte del Sprint 6 no se reportó por separado: SCRUM-36 consolidó los Sprints 6 y 7 en un solo corte.

Sheet Metrica dual
A1: Métrica dual: consumo frente a alcance entregado (backlog de Jira, proyecto SCRUM)
A3: Sprint del curso | B3: Sprint en Jira | C3: Tareas | D3: SP comprometidos | E3: SP cerrados | F3: % del sprint cerrado | G3: SP cerrados acumulados
A4: Sprint 6 | B4: SCRUM Sprint 1 | C4: 20 | D4: 96 | E4: 96 | F4: =IF(D4=0,0,E4/D4) | G4: =SUM($E$4:E4)
A5: Sprint 7 | B5: SCRUM Sprint 2 | C5: 12 | D5: 44 | E5: 44 | F5: =IF(D5=0,0,E5/D5) | G5: =SUM($E$4:E5)
A6: Sprint 8 | B6: SCRUM Sprint 3 | C6: 15 | D6: 56 | E6: 56 | F6: =IF(D6=0,0,E6/D6) | G6: =SUM($E$4:E6)
A7: Sprint 9 | B7: SCRUM Sprint 4 | C7: 12 | D7: 42 | E7: 42 | F7: =IF(D7=0,0,E7/D7) | G7: =SUM($E$4:E7)
A8: Sprint 10 | B8: SCRUM Sprint 5 | C8: 31 | D8: 118 | E8: 92 | F8: =IF(D8=0,0,E8/D8) | G8: =SUM($E$4:E8)
A9: Backlog sin sprint | B9: — | C9: 3 | D9: 5 | E9: 0 | F9: 0 | G9: =G8
A10: Total del backlog | C10: =SUM(C4:C9) | D10: =SUM(D4:D9) | E10: =SUM(E4:E9) | F10: =E10/D10
A12: Backlog sin sprint: HU-36 (publicación en APIs de redes sociales, 5 SP) y dos incidencias sin estimar (SCRUM-104, SCRUM-105). Las épicas no tienen SP y no cuentan. Los Sprints 1 a 5 del curso son anteriores al tablero de Jira.
A14: Indicador | B14: Valor | C14: Nota
A15: Alcance cerrado (SP cerrados / SP del backlog) | B15: =E10/D10 | C15: Alcance entregado
A16: Esfuerzo consumido del total estimado por PCU | B16: =Calculo!D38 | C16: Consumo, ciclo completo
A17: Costo consumido del total, K = 1.5 | B17: =Calculo!D41 | C17: Consumo, ciclo completo
A18: Esfuerzo consumido de la actividad de implementación | B18: =Calculo!D39 | C18: Consumo, base del 40 %
A19: Alcance cerrado por cada punto de consumo (ciclo completo) | B19: =B15/B16 | C19: Veces
A20: Alcance cerrado por cada punto de consumo (implementación) | B20: =B15/B18 | C20: Veces
A21: H/H por SP cerrado, Sprints 8 a 10 | B21: =Calculo!E32/(E6+E7+E8) | C21: Productividad observada

Sheet Texto
A1: Texto para el informe
A2: Fuente de las horas: los LOGT del Sprint 10 de los cinco integrantes (hojas LOGT de este libro), construidos con la estimación original de cada tarea del Sprint 10 en Jira (SCRUM Sprint 5, 14/10/2026 – 27/10/2026), igual que en los cortes de los Sprints 8 y 9. Las horas de los Sprints 8 y 9 vienen de sus libros (ejecucion-presupuesto-sprint8.xlsx y ejecucion-presupuesto-sprint9.xlsx) y el acumulado al Sprint 7, de SCRUM-36.
A3: En el Sprint 10 se registran 298.00 H/H: Pablo Vásquez 73.00, Jonathan Tubac 58.00, Juan Francisco Montenegro Aguirre 74.00, Alejandra Sarai Avilés González 47.00, Ivana Cristina Figueroa Diemek 46.00. Con ello el equipo cierra el proyecto con 1,197.00 H/H acumuladas, el 15.72% del esfuerzo total estimado de 7,613.67 H/H: 3.91 puntos porcentuales más que en el corte del Sprint 9 (11.81%) y 6.25 más que en el del Sprint 7 (9.47%).
A4: Con la tarifa individual de cada integrante, el Sprint 10 suma Q 20,668.50 con K = 1.5 y Q 27,558.00 con K = 2. El monto ejecutado acumulado al cierre es de Q 81,509.70 con K = 1.5, el 15.93% del costo total estimado (Q 511,638.46), y de Q 108,679.60 con K = 2, el 15.93% de Q 682,184.62: la misma proporción, porque K multiplica igual el monto y la base. Frente al Sprint 9, el porcentaje de costo avanza 4.04 puntos porcentuales; frente al Sprint 7, 6.41. Quedan sin ejercer Q 430,128.76 (K = 1.5) y 6,416.67 H/H.
A5: Frente a la actividad de implementación (40 % del esfuerzo, 3,045.47 H/H), el consumo al cierre es del 39.30% en horas y del 39.83% en costo.
A6: Métrica dual: el backlog de Jira suma 361 SP en tareas; al cierre están cerrados 330 SP, el 91.41% del alcance. Del Sprint 10 quedan abiertos 26 SP (L-4, P-2, P-3, RTF-1, CI-1, TEST-3, DEMO-1, BUD-1 y UI-1, en curso o en revisión) y fuera de sprint queda HU-36 (5 SP). Se entregó el 91.4% del alcance consumiendo el 15.7% del esfuerzo estimado: 5.8 puntos de alcance por cada punto de consumo frente al ciclo completo, y 2.3 frente a la implementación. En los Sprints 8 a 10 el equipo cerró 190 SP con 476.00 H/H, 2.51 H/H por SP.
A7: Lectura final sobre la estimación por PCU. El producto se entregó con el 15.9% del presupuesto estimado y el 15.7% del esfuerzo: la estimación por Puntos de Casos de Uso sobreestimó el costo real unas 6.4 veces. No es un error de cálculo sino de alcance del método: Karner estima el ciclo de vida profesional completo (análisis, diseño, implementación, pruebas, despliegue y gestión, con dedicación de tiempo completo) y funciona como cota superior. Comparado con la actividad de implementación, que es lo que el equipo ejecutó de verdad, el consumo llega al 39.3%: esa base de 40 % fue la referencia más cercana durante todo el proyecto, y aun así quedó holgada. La brecha es de esfuerzo, no de tarifa: el porcentaje de costo (15.93%) casi coincide con el de horas (15.72%), porque la tarifa individual ponderada por las horas de cada integrante queda muy cerca de la tarifa promedio con la que se valoró el PCU. Además, las horas se registran con la estimación de cada tarea en Jira, que tiende a quedarse corta frente al tiempo real (reuniones, revisión de PR, aprendizaje de herramientas), así que el consumo real puede ser algo mayor sin cambiar la conclusión. Para un proyecto similar, el PCU sirve como techo presupuestario; la planificación operativa debe apoyarse en la velocidad observada (2.51 H/H por SP en los últimos tres sprints) y en una base de implementación, no en el esfuerzo de ciclo completo.
A8: Nota: los LOGT del Sprint 10 están reconstruidos a partir de Jira y de las fechas de los commits; cada integrante debe revisar su hoja antes de la entrega. Las tareas en curso o en revisión al 27/10/2026 cuentan con su estimación completa; DEMO-1, aún «Por hacer», no suma horas: si se realiza antes de la entrega, se agregan sus 5 H/H a la hoja de Alejandra.

Sheet LOGT Vásquez
A1: Registro de tiempo (LOGT) · Sprint 10
A3: Integrante | B3: Pablo Vásquez
A4: Carné | B4: 24757
A5: Sprint | B5: Sprint 10 (Jira: SCRUM Sprint 5), 14/10/2026 – 27/10/2026
A6: Proyecto | B6: Kontrol
A8: Fecha | B8: Inicio | C8: Fin | D8: Interrupción (min) | E8: Δ Tiempo (min) | F8: Fase / actividad | G8: Tarea Jira | H8: Comentarios
A9: 46309 | B9: 0.70833333 | C9: 0.75 | D9: 0 | E9: =ROUND(MOD(C9-B9,1)*1440,0)-D9 | F9: Planificación | G9: SCRUM-77 | H9: Alcance, criterios de aceptación y plan de trabajo de DT-11
A10: 46309 | B10: 0.77083333 | C10: 0.91666667 | D10: 0 | E10: =ROUND(MOD(C10-B10,1)*1440,0)-D10 | F10: Código | G10: SCRUM-77 | H10: Implementación: ESLint, Prettier y paso de lint en el pipeline
A11: 46309 | B11: 0.9375 | C11: 0.95833333 | D11: 0 | E11: =ROUND(MOD(C11-B11,1)*1440,0)-D11 | F11: Documentación | G11: SCRUM-77 | H11: Redacción, revisión y PR: ESLint, Prettier y paso de lint en el pipeline
A12: 46309 | B12: 0.97916667 | C12: 0.020833333 | D12: 0 | E12: =ROUND(MOD(C12-B12,1)*1440,0)-D12 | F12: Planificación | G12: SCRUM-94 | H12: Alcance, criterios de aceptación y plan de trabajo de PROD-1
A13: 46310 | B13: 0.70833333 | C13: 0.83333333 | D13: 0 | E13: =ROUND(MOD(C13-B13,1)*1440,0)-D13 | F13: Pruebas | G13: SCRUM-77 | H13: Pruebas y verificación: ESLint, Prettier y paso de lint en el pipeline
A14: 46310 | B14: 0.85416667 | C14: 0.98958333 | D14: 15 | E14: =ROUND(MOD(C14-B14,1)*1440,0)-D14 | F14: Código | G14: SCRUM-94 | H14: Implementación: Servidor de producción con URL pública verificable
A15: 46311 | B15: 0.70833333 | C15: 0.8125 | D15: 0 | E15: =ROUND(MOD(C15-B15,1)*1440,0)-D15 | F15: Código | G15: SCRUM-69 | H15: Implementación: Actualizar dependencias vulnerables y auditar en CI
A16: 46311 | B16: 0.83333333 | C16: 0.95833333 | D16: 0 | E16: =ROUND(MOD(C16-B16,1)*1440,0)-D16 | F16: Código | G16: SCRUM-94 | H16: Implementación: Servidor de producción con URL pública verificable (parte 2)
A17: 46312 | B17: 0.375 | C17: 0.41666667 | D17: 0 | E17: =ROUND(MOD(C17-B17,1)*1440,0)-D17 | F17: Planificación | G17: SCRUM-106 | H17: Alcance, criterios de aceptación y plan de trabajo de UI-2
A18: 46312 | B18: 0.4375 | C18: 0.5625 | D18: 0 | E18: =ROUND(MOD(C18-B18,1)*1440,0)-D18 | F18: Código | G18: SCRUM-106 | H18: Implementación: Consistencia de superficies, correcciones de layout y página 404
A19: 46312 | B19: 0.58333333 | C19: 0.70833333 | D19: 0 | E19: =ROUND(MOD(C19-B19,1)*1440,0)-D19 | F19: Código | G19: SCRUM-106 | H19: Implementación: Consistencia de superficies, correcciones de layout y página 404 (parte 2)
A20: 46312 | B20: 0.72916667 | C20: 0.75 | D20: 0 | E20: =ROUND(MOD(C20-B20,1)*1440,0)-D20 | F20: Documentación | G20: SCRUM-106 | H20: Redacción, revisión y PR: Consistencia de superficies, correcciones de layout y página 404
... A41: 46322 | B41: 0.77083333 | C41: 0.92708333 | D41: 15 | E41: =ROUND(MOD(C41-B41,1)*1440,0)-D41 | F41: Documentación | G41: SCRUM-99 | H41: Redacción, revisión y PR: Evidencia de integración continua y comparación de rendimiento
A42: Total | D42: =SUM(D9:D41) | E42: =SUM(E9:E41)
A43: Total en horas | E43: =E42/60
A45: Nota: registro reconstruido a partir de la estimación original de cada tarea en Jira y de las fechas de los commits del sprint. Cada integrante debe revisarlo y ajustarlo a su tiempo real.

Sheet LOGT Tubac
A1: Registro de tiempo (LOGT) · Sprint 10
A3: Integrante | B3: Jonathan Tubac
A4: Carné | B4: 24484
A5: Sprint | B5: Sprint 10 (Jira: SCRUM Sprint 5), 14/10/2026 – 27/10/2026
A6: Proyecto | B6: Kontrol
A8: Fecha | B8: Inicio | C8: Fin | D8: Interrupción (min) | E8: Δ Tiempo (min) | F8: Fase / actividad | G8: Tarea Jira | H8: Comentarios
A9: 46310 | B9: 0.70833333 | C9: 0.75 | D9: 0 | E9: =ROUND(MOD(C9-B9,1)*1440,0)-D9 | F9: Planificación | G9: SCRUM-78 | H9: Alcance, criterios de aceptación y plan de trabajo de L-7
A10: 46310 | B10: 0.77083333 | C10: 0.91666667 | D10: 0 | E10: =ROUND(MOD(C10-B10,1)*1440,0)-D10 | F10: Documentación | G10: SCRUM-78 | H10: Redacción, revisión y PR: Análisis de brecha fiscal del POS frente al régimen FEL de la SAT
A11: 46311 | B11: 0.70833333 | C11: 0.86458333 | D11: 15 | E11: =ROUND(MOD(C11-B11,1)*1440,0)-D11 | F11: Documentación | G11: SCRUM-78 | H11: Redacción, revisión y PR: Análisis de brecha fiscal del POS frente al régimen FEL de la SAT (parte 2)
A12: 46313 | B12: 0.375 | C12: 0.41666667 | D12: 0 | E12: =ROUND(MOD(C12-B12,1)*1440,0)-D12 | F12: Planificación | G12: SCRUM-95 | H12: Alcance, criterios de aceptación y plan de trabajo de TEST-1
A13: 46313 | B13: 0.4375 | C13: 0.5625 | D13: 0 | E13: =ROUND(MOD(C13-B13,1)*1440,0)-D13 | F13: Código | G13: SCRUM-95 | H13: Implementación: Suite de pruebas de integración en el pipeline de CI
A14: 46314 | B14: 0.70833333 | C14: 0.84375 | D14: 15 | E14: =ROUND(MOD(C14-B14,1)*1440,0)-D14 | F14: Código | G14: SCRUM-95 | H14: Implementación: Suite de pruebas de integración en el pipeline de CI (parte 2)
A15: 46314 | B15: 0.86458333 | C15: 0.98958333 | D15: 0 | E15: =ROUND(MOD(C15-B15,1)*1440,0)-D15 | F15: Código | G15: SCRUM-95 | H15: Implementación: Suite de pruebas de integración en el pipeline de CI (parte 3)
A16: 46316 | B16: 0.70833333 | C16: 0.8125 | D16: 0 | E16: =ROUND(MOD(C16-B16,1)*1440,0)-D16 | F16: Pruebas | G16: SCRUM-95 | H16: Pruebas y verificación: Suite de pruebas de integración en el pipeline de CI
A17: 46316 | B17: 0.83333333 | C17: 0.85416667 | D17: 0 | E17: =ROUND(MOD(C17-B17,1)*1440,0)-D17 | F17: Documentación | G17: SCRUM-95 | H17: Redacción, revisión y PR: Suite de pruebas de integración en el pipeline de CI
A18: 46317 | B18: 0.70833333 | C18: 0.75 | D18: 0 | E18: =ROUND(MOD(C18-B18,1)*1440,0)-D18 | F18: Planificación | G18: SCRUM-87 | H18: Alcance, criterios de aceptación y plan de trabajo de L-3
A19: 46317 | B19: 0.77083333 | C19: 0.91666667 | D19: 0 | E19: =ROUND(MOD(C19-B19,1)*1440,0)-D19 | F19: Código | G19: SCRUM-87 | H19: Implementación: Política de cookies y almacenamiento local, con banner de consentimiento
A20: 46318 | B20: 0.70833333 | C20: 0.84375 | D20: 15 | E20: =ROUND(MOD(C20-B20,1)*1440,0)-D20 | F20: Pruebas | G20: SCRUM-87 | H20: Pruebas y verificación: Política de cookies y almacenamiento local, con banner de consentimiento
... A33: 46322 | B33: 0.94791667 | C33: 0.96875 | D33: 0 | E33: =ROUND(MOD(C33-B33,1)*1440,0)-D33 | F33: Documentación | G33: SCRUM-88 | H33: Redacción, revisión y PR: Implementación de los documentos legales en la aplicación
A34: Total | D34: =SUM(D9:D33) | E34: =SUM(E9:E33)
A35: Total en horas | E35: =E34/60
A37: Nota: registro reconstruido a partir de la estimación original de cada tarea en Jira y de las fechas de los commits del sprint. Cada integrante debe revisarlo y ajustarlo a su tiempo real.

Sheet LOGT Montenegro
A1: Registro de tiempo (LOGT) · Sprint 10
A3: Integrante | B3: Juan Francisco Montenegro Aguirre
A4: Carné
A5: Sprint | B5: Sprint 10 (Jira: SCRUM Sprint 5), 14/10/2026 – 27/10/2026
A6: Proyecto | B6: Kontrol
A8: Fecha | B8: Inicio | C8: Fin | D8: Interrupción (min) | E8: Δ Tiempo (min) | F8: Fase / actividad | G8: Tarea Jira | H8: Comentarios
A9: 46309 | B9: 0.70833333 | C9: 0.75 | D9: 0 | E9: =ROUND(MOD(C9-B9,1)*1440,0)-D9 | F9: Planificación | G9: SCRUM-76 | H9: Alcance, criterios de aceptación y plan de trabajo de L-0
A10: 46309 | B10: 0.77083333 | C10: 0.91666667 | D10: 0 | E10: =ROUND(MOD(C10-B10,1)*1440,0)-D10 | F10: Documentación | G10: SCRUM-76 | H10: Redacción, revisión y PR: Investigación del marco legal aplicable y estándar de cumplimiento adoptado
A11: 46310 | B11: 0.70833333 | C11: 0.86458333 | D11: 15 | E11: =ROUND(MOD(C11-B11,1)*1440,0)-D11 | F11: Documentación | G11: SCRUM-76 | H11: Redacción, revisión y PR: Investigación del marco legal aplicable y estándar de cumplimiento adoptado (parte 2)
A12: 46311 | B12: 0.70833333 | C12: 0.75 | D12: 0 | E12: =ROUND(MOD(C12-B12,1)*1440,0)-D12 | F12: Planificación | G12: SCRUM-83 | H12: Alcance, criterios de aceptación y plan de trabajo de L-1
A13: 46311 | B13: 0.77083333 | C13: 0.89583333 | D13: 0 | E13: =ROUND(MOD(C13-B13,1)*1440,0)-D13 | F13: Documentación | G13: SCRUM-83 | H13: Redacción, revisión y PR: Términos y Condiciones de Uso
A14: 46311 | B14: 0.91666667 | C14: 0.95833333 | D14: 0 | E14: =ROUND(MOD(C14-B14,1)*1440,0)-D14 | F14: Planificación | G14: SCRUM-84 | H14: Alcance, criterios de aceptación y plan de trabajo de L-2
A15: 46312 | B15: 0.375 | C15: 0.41666667 | D15: 0 | E15: =ROUND(MOD(C15-B15,1)*1440,0)-D15 | F15: Planificación | G15: SCRUM-80 | H15: Alcance, criterios de aceptación y plan de trabajo de L-8
A16: 46312 | B16: 0.4375 | C16: 0.5625 | D16: 0 | E16: =ROUND(MOD(C16-B16,1)*1440,0)-D16 | F16: Documentación | G16: SCRUM-83 | H16: Redacción, revisión y PR: Términos y Condiciones de Uso (parte 2)
A17: 46312 | B17: 0.58333333 | C17: 0.71875 | D17: 15 | E17: =ROUND(MOD(C17-B17,1)*1440,0)-D17 | F17: Documentación | G17: SCRUM-84 | H17: Redacción, revisión y PR: Política de Privacidad e inventario de datos personales del sistema
A18: 46313 | B18: 0.375 | C18: 0.52083333 | D18: 0 | E18: =ROUND(MOD(C18-B18,1)*1440,0)-D18 | F18: Documentación | G18: SCRUM-80 | H18: Redacción, revisión y PR: Licencia del repositorio y auditoría de licencias de terceros
A19: 46313 | B19: 0.54166667 | C19: 0.66666667 | D19: 0 | E19: =ROUND(MOD(C19-B19,1)*1440,0)-D19 | F19: Documentación | G19: SCRUM-83 | H19: Redacción, revisión y PR: Términos y Condiciones de Uso (parte 3)
A20: 46314 | B20: 0.70833333 | C20: 0.84375 | D20: 15 | E20: =ROUND(MOD(C20-B20,1)*1440,0)-D20 | F20: Documentación | G20: SCRUM-83 | H20: Redacción, revisión y PR: Términos y Condiciones de Uso (parte 4)
... A37: 46322 | B37: 0.83333333 | C37: 0.97916667 | D37: 0 | E37: =ROUND(MOD(C37-B37,1)*1440,0)-D37 | F37: Documentación | G37: SCRUM-85 | H37: Redacción, revisión y PR: Adenda de tratamiento de datos para los clientes de Kontrol (parte 2)
A38: Total | D38: =SUM(D9:D37) | E38: =SUM(E9:E37)
A39: Total en horas | E39: =E38/60
A41: Nota: registro reconstruido a partir de la estimación original de cada tarea en Jira y de las fechas de los commits del sprint. Cada integrante debe revisarlo y ajustarlo a su tiempo real.

Sheet LOGT Avilés
A1: Registro de tiempo (LOGT) · Sprint 10
A3: Integrante | B3: Alejandra Sarai Avilés González
A4: Carné
A5: Sprint | B5: Sprint 10 (Jira: SCRUM Sprint 5), 14/10/2026 – 27/10/2026
A6: Proyecto | B6: Kontrol
A8: Fecha | B8: Inicio | C8: Fin | D8: Interrupción (min) | E8: Δ Tiempo (min) | F8: Fase / actividad | G8: Tarea Jira | H8: Comentarios
A9: 46310 | B9: 0.70833333 | C9: 0.75 | D9: 0 | E9: =ROUND(MOD(C9-B9,1)*1440,0)-D9 | F9: Planificación | G9: SCRUM-75 | H9: Alcance, criterios de aceptación y plan de trabajo de DT-07
A10: 46310 | B10: 0.77083333 | C10: 0.89583333 | D10: 0 | E10: =ROUND(MOD(C10-B10,1)*1440,0)-D10 | F10: Código | G10: SCRUM-75 | H10: Implementación: Capa de acceso a API unificada en el frontend
A11: 46311 | B11: 0.70833333 | C11: 0.84375 | D11: 15 | E11: =ROUND(MOD(C11-B11,1)*1440,0)-D11 | F11: Código | G11: SCRUM-75 | H11: Implementación: Capa de acceso a API unificada en el frontend (parte 2)
A12: 46311 | B12: 0.86458333 | C12: 0.98958333 | D12: 0 | E12: =ROUND(MOD(C12-B12,1)*1440,0)-D12 | F12: Código | G12: SCRUM-75 | H12: Implementación: Capa de acceso a API unificada en el frontend (parte 3)
A13: 46312 | B13: 0.375 | C13: 0.47916667 | D13: 0 | E13: =ROUND(MOD(C13-B13,1)*1440,0)-D13 | F13: Pruebas | G13: SCRUM-75 | H13: Pruebas y verificación: Capa de acceso a API unificada en el frontend
A14: 46312 | B14: 0.5 | C14: 0.52083333 | D14: 0 | E14: =ROUND(MOD(C14-B14,1)*1440,0)-D14 | F14: Documentación | G14: SCRUM-75 | H14: Redacción, revisión y PR: Capa de acceso a API unificada en el frontend
A15: 46314 | B15: 0.70833333 | C15: 0.8125 | D15: 0 | E15: =ROUND(MOD(C15-B15,1)*1440,0)-D15 | F15: Código | G15: SCRUM-66 | H15: Implementación: Aislar las vistas temporales del agente dentro de la transacción
A16: 46314 | B16: 0.83333333 | C16: 0.91666667 | D16: 0 | E16: =ROUND(MOD(C16-B16,1)*1440,0)-D16 | F16: Pruebas | G16: SCRUM-66 | H16: Pruebas y verificación: Aislar las vistas temporales del agente dentro de la transacción
A17: 46314 | B17: 0.9375 | C17: 0.95833333 | D17: 0 | E17: =ROUND(MOD(C17-B17,1)*1440,0)-D17 | F17: Documentación | G17: SCRUM-66 | H17: Redacción, revisión y PR: Aislar las vistas temporales del agente dentro de la transacción
A18: 46315 | B18: 0.70833333 | C18: 0.75 | D18: 0 | E18: =ROUND(MOD(C18-B18,1)*1440,0)-D18 | F18: Planificación | G18: SCRUM-89 | H18: Alcance, criterios de aceptación y plan de trabajo de P-1
A19: 46315 | B19: 0.77083333 | C19: 0.89583333 | D19: 0 | E19: =ROUND(MOD(C19-B19,1)*1440,0)-D19 | F19: Código | G19: SCRUM-89 | H19: Implementación: Exportación de datos y borrado de cuenta
A20: 46316 | B20: 0.70833333 | C20: 0.84375 | D20: 15 | E20: =ROUND(MOD(C20-B20,1)*1440,0)-D20 | F20: Código | G20: SCRUM-89 | H20: Implementación: Exportación de datos y borrado de cuenta (parte 2)
... A30: 46321 | B30: 0.70833333 | C30: 0.72916667 | D30: 0 | E30: =ROUND(MOD(C30-B30,1)*1440,0)-D30 | F30: Documentación | G30: SCRUM-90 | H30: Redacción, revisión y PR: Política de respaldos con restauración probada
A31: Total | D31: =SUM(D9:D30) | E31: =SUM(E9:E30)
A32: Total en horas | E32: =E31/60
A34: Nota: registro reconstruido a partir de la estimación original de cada tarea en Jira y de las fechas de los commits del sprint. Cada integrante debe revisarlo y ajustarlo a su tiempo real.

Sheet LOGT Figueroa
A1: Registro de tiempo (LOGT) · Sprint 10
A3: Integrante | B3: Ivana Cristina Figueroa Diemek
A4: Carné
A5: Sprint | B5: Sprint 10 (Jira: SCRUM Sprint 5), 14/10/2026 – 27/10/2026
A6: Proyecto | B6: Kontrol
A8: Fecha | B8: Inicio | C8: Fin | D8: Interrupción (min) | E8: Δ Tiempo (min) | F8: Fase / actividad | G8: Tarea Jira | H8: Comentarios
A9: 46312 | B9: 0.375 | C9: 0.41666667 | D9: 0 | E9: =ROUND(MOD(C9-B9,1)*1440,0)-D9 | F9: Planificación | G9: SCRUM-79 | H9: Alcance, criterios de aceptación y plan de trabajo de HU-32b
A10: 46312 | B10: 0.4375 | C10: 0.5625 | D10: 0 | E10: =ROUND(MOD(C10-B10,1)*1440,0)-D10 | F10: Código | G10: SCRUM-79 | H10: Implementación: Cierre de la Fase 2 de la identidad visual v2
A11: 46313 | B11: 0.375 | C11: 0.51041667 | D11: 15 | E11: =ROUND(MOD(C11-B11,1)*1440,0)-D11 | F11: Código | G11: SCRUM-79 | H11: Implementación: Cierre de la Fase 2 de la identidad visual v2 (parte 2)
A12: 46313 | B12: 0.53125 | C12: 0.65625 | D12: 0 | E12: =ROUND(MOD(C12-B12,1)*1440,0)-D12 | F12: Código | G12: SCRUM-79 | H12: Implementación: Cierre de la Fase 2 de la identidad visual v2 (parte 3)
A13: 46314 | B13: 0.70833333 | C13: 0.8125 | D13: 0 | E13: =ROUND(MOD(C13-B13,1)*1440,0)-D13 | F13: Pruebas | G13: SCRUM-79 | H13: Pruebas y verificación: Cierre de la Fase 2 de la identidad visual v2
A14: 46314 | B14: 0.83333333 | C14: 0.85416667 | D14: 0 | E14: =ROUND(MOD(C14-B14,1)*1440,0)-D14 | F14: Documentación | G14: SCRUM-79 | H14: Redacción, revisión y PR: Cierre de la Fase 2 de la identidad visual v2
A15: 46316 | B15: 0.70833333 | C15: 0.8125 | D15: 0 | E15: =ROUND(MOD(C15-B15,1)*1440,0)-D15 | F15: Documentación | G15: SCRUM-91 | H15: Redacción, revisión y PR: Procedimiento de respuesta a incidentes y notificación de brechas
A16: 46316 | B16: 0.83333333 | C16: 0.95833333 | D16: 0 | E16: =ROUND(MOD(C16-B16,1)*1440,0)-D16 | F16: Código | G16: SCRUM-92 | H16: Implementación: Carga diferida del logo 3D y los fondos animados, y separación de chunks
A17: 46317 | B17: 0.70833333 | C17: 0.82291667 | D17: 15 | E17: =ROUND(MOD(C17-B17,1)*1440,0)-D17 | F17: Documentación | G17: SCRUM-91 | H17: Redacción, revisión y PR: Procedimiento de respuesta a incidentes y notificación de brechas (parte 2)
A18: 46317 | B18: 0.84375 | C18: 0.88541667 | D18: 0 | E18: =ROUND(MOD(C18-B18,1)*1440,0)-D18 | F18: Planificación | G18: SCRUM-92 | H18: Alcance, criterios de aceptación y plan de trabajo de DT-17
A19: 46317 | B19: 0.90625 | C19: 0.010416667 | D19: 0 | E19: =ROUND(MOD(C19-B19,1)*1440,0)-D19 | F19: Pruebas | G19: SCRUM-92 | H19: Pruebas y verificación: Carga diferida del logo 3D y los fondos animados, y separación de chunks
A20: 46318 | B20: 0.70833333 | C20: 0.84375 | D20: 15 | E20: =ROUND(MOD(C20-B20,1)*1440,0)-D20 | F20: Código | G20: SCRUM-92 | H20: Implementación: Carga diferida del logo 3D y los fondos animados, y separación de chunks (parte 2)
... A29: 46321 | B29: 0.83333333 | C29: 0.94791667 | D29: 15 | E29: =ROUND(MOD(C29-B29,1)*1440,0)-D29 | F29: Documentación | G29: SCRUM-100 | H29: Redacción, revisión y PR: Reporte consolidado de pruebas de regresión de la refactorización (parte 2)
A30: Total | D30: =SUM(D9:D29) | E30: =SUM(E9:E29)
A31: Total en horas | E31: =E30/60
A33: Nota: registro reconstruido a partir de la estimación original de cada tarea en Jira y de las fechas de los commits del sprint. Cada integrante debe revisarlo y ajustarlo a su tiempo real.
